I'm sorry, but an uncaught exception occurred.

While running game code:
  File "game/script.rpy", line 343, in script
    $ relacje.relup("Kalach", 1)
  File "game/script.rpy", line 343, in <module>
    $ relacje.relup("Kalach", 1)
  File "game/script.rpy", line 79, in relup
    self.post.append(post)
NameError: name 'self' is not defined

-- Full Traceback ------------------------------------------------------------

Full traceback:
  File "game/script.rpy", line 343, in script
    $ relacje.relup("Kalach", 1)
  File "C:\Users\Lenovo\Desktop\Renpy\renpy-8.1.3-sdk\renpy\ast.py", line 1138, in execute
    renpy.python.py_exec_bytecode(self.code.bytecode, self.hide, store=self.store)
  File "C:\Users\Lenovo\Desktop\Renpy\renpy-8.1.3-sdk\renpy\python.py", line 1122, in py_exec_bytecode
    exec(bytecode, globals, locals)
  File "game/script.rpy", line 343, in <module>
    $ relacje.relup("Kalach", 1)
  File "game/script.rpy", line 79, in relup
    self.post.append(post)
NameError: name 'self' is not defined

Windows-10-10.0.19045 AMD64
Ren'Py 8.1.3.23091805
CyberDzban 0.0000000002
Wed Nov 15 12:08:26 2023
